<?xml version='1.0' encoding='UTF-8'?>
<testsuite errors="0" failures="1" hostname="wally" name="mytest.test feature" skipped="0" tests="3" time="0.005808" timestamp="2018-09-25T15:56:06.970842">
    <testcase classname="mytest.test feature" name="a scenario" status="passed" time="0.00114"><system-out>
<![CDATA[
@scenario.begin
  Scenario: a scenario
    Given I run a step with no substeps ... passed in 0.000s
    And I run a step with a passing substep ... passed in 0.001s
    Then this happens ... passed in 0.000s

@scenario.end
--------------------------------------------------------------------------------
]]>
</system-out></testcase>
<testcase classname="mytest.test feature" name="failing scenario" status="failed" time="0.001163"><failure message="FAILED SUB-STEP: Then failing substep&#10;Substep info: Assertion Failed: failed this one&#10;Traceback (of failed substep):&#10;  File &quot;/home/mmccrorey/virtualenv/new_arch/local/lib/python2.7/site-packages/behave-1.2.6-py2.7.egg/behave/model.py&quot;, line 1329, in run&#10;    match.run(runner.context)&#10;  File &quot;/home/mmccrorey/virtualenv/new_arch/local/lib/python2.7/site-packages/behave-1.2.6-py2.7.egg/behave/matchers.py&quot;, line 98, in run&#10;    self.func(context, *args, **kwargs)&#10;  File &quot;features/steps/steps.py&quot;, line 40, in failing_substep&#10;    assert False, &quot;failed this one&quot;&#10;" type="AssertionError">
<![CDATA[
Failing step: Given I run a step with a failing substep ... failed in 0.001s
Location: features/mytest.feature:16
Assertion Failed: FAILED SUB-STEP: Then failing substep
Substep info: Assertion Failed: failed this one
Traceback (of failed substep):
  File "/home/mmccrorey/virtualenv/new_arch/local/lib/python2.7/site-packages/behave-1.2.6-py2.7.egg/behave/model.py", line 1329, in run
    match.run(runner.context)
  File "/home/mmccrorey/virtualenv/new_arch/local/lib/python2.7/site-packages/behave-1.2.6-py2.7.egg/behave/matchers.py", line 98, in run
    self.func(context, *args, **kwargs)
  File "features/steps/steps.py", line 40, in failing_substep
    assert False, "failed this one"

Captured logging:
INFO:mtaf.environment:step.name: I run a step with a failing substep
INFO:mtaf.environment:step.name: failing substep
INFO:mtaf.environment:EXCEPTION in step failing substep
INFO:mtaf.environment:EXCEPTION in step I run a step with a failing substep]]>
</failure><system-out>
<![CDATA[
@scenario.begin

  @bar
  Scenario: failing scenario
    Given I run a step with a failing substep ... failed in 0.001s
    Given I run a step with a passing substep ... skipped in 0.000s
    And I run a step with a fake substep ... skipped in 0.000s
    Given I run a step with substeps that have substeps ... skipped in 0.000s
    Then this happens ... skipped in 0.000s

@scenario.end
--------------------------------------------------------------------------------
]]>
</system-out></testcase>
<testcase classname="mytest.test feature" name="another scenario" status="passed" time="0.003505"><system-out>
<![CDATA[
@scenario.begin

  @bar
  Scenario: another scenario
    Given I run a step with no substeps ... passed in 0.000s
    Given I run a step with a passing substep ... passed in 0.001s
    And I run a step with a fake substep ... passed in 0.001s
    Given I run a step with substeps that have substeps ... passed in 0.002s
    Then this happens ... passed in 0.000s

@scenario.end
--------------------------------------------------------------------------------
]]>
<step>
    name="Given I run a step with no substeps ... passed in 0.000s"
</step>
<step>
    name="Given I run a step with a passing substeps ... passed in 0.000s"
</step>
<step>
    name="Given I run a step with a fake substeps ... passed in 0.000s"
</step>
</system-out></testcase></testsuite>
